[2023-01-23T11:14:55.771-0300] {taskinstance.py:1087} INFO - Dependencies all met for <TaskInstance: raw_opt_t_fatura.get_last_date manual__2023-01-23T14:14:28.103245+00:00 [queued]>
[2023-01-23T11:14:56.420-0300] {taskinstance.py:1087} INFO - Dependencies all met for <TaskInstance: raw_opt_t_fatura.get_last_date manual__2023-01-23T14:14:28.103245+00:00 [queued]>
[2023-01-23T11:14:56.420-0300] {taskinstance.py:1283} INFO - 
--------------------------------------------------------------------------------
[2023-01-23T11:14:56.420-0300] {taskinstance.py:1284} INFO - Starting attempt 1 of 1
[2023-01-23T11:14:56.421-0300] {taskinstance.py:1285} INFO - 
--------------------------------------------------------------------------------
[2023-01-23T11:14:56.871-0300] {taskinstance.py:1304} INFO - Executing <Task(DatabricksSubmitRunOperator): get_last_date> on 2023-01-23 14:14:28.103245+00:00
[2023-01-23T11:14:56.876-0300] {standard_task_runner.py:55} INFO - Started process 1101145 to run task
[2023-01-23T11:14:56.880-0300] {standard_task_runner.py:82} INFO - Running: ['airflow', 'tasks', 'run', 'raw_opt_t_fatura', 'get_last_date', 'manual__2023-01-23T14:14:28.103245+00:00', '--job-id', '1172', '--raw', '--subdir', 'DAGS_FOLDER/raw/dock_opt/raw_opt_t_fatura.py', '--cfg-path', '/tmp/tmpiuaypc56']
[2023-01-23T11:14:56.883-0300] {standard_task_runner.py:83} INFO - Job 1172: Subtask get_last_date
[2023-01-23T11:14:59.955-0300] {task_command.py:389} INFO - Running <TaskInstance: raw_opt_t_fatura.get_last_date manual__2023-01-23T14:14:28.103245+00:00 [running]> on host vm-airflow-01
[2023-01-23T11:15:02.790-0300] {taskinstance.py:1511} INFO - Exporting the following env vars:
AIRFLOW_CTX_DAG_OWNER=matheus.rodrigues@fortbrasil.com.br
AIRFLOW_CTX_DAG_ID=raw_opt_t_fatura
AIRFLOW_CTX_TASK_ID=get_last_date
AIRFLOW_CTX_EXECUTION_DATE=2023-01-23T14:14:28.103245+00:00
AIRFLOW_CTX_TRY_NUMBER=1
AIRFLOW_CTX_DAG_RUN_ID=manual__2023-01-23T14:14:28.103245+00:00
[2023-01-23T11:15:03.286-0300] {base.py:73} INFO - Using connection ID 'adb' for task execution.
[2023-01-23T11:15:03.473-0300] {databricks_base.py:424} INFO - Using token auth. For security reasons, please set token in Password field instead of extra
[2023-01-23T11:15:04.342-0300] {taskinstance.py:1772} ERROR - Task failed with exception
Traceback (most recent call last):
  File "/home/airflow/.local/lib/python3.10/site-packages/airflow/providers/databricks/hooks/databricks_base.py", line 515, in _do_api_call
    for attempt in self._get_retry_object():
  File "/home/airflow/.local/lib/python3.10/site-packages/tenacity/__init__.py", line 384, in __iter__
    do = self.iter(retry_state=retry_state)
  File "/home/airflow/.local/lib/python3.10/site-packages/tenacity/__init__.py", line 351, in iter
    return fut.result()
  File "/usr/lib/python3.10/concurrent/futures/_base.py", line 451, in result
    return self.__get_result()
  File "/usr/lib/python3.10/concurrent/futures/_base.py", line 403, in __get_result
    raise self._exception
  File "/home/airflow/.local/lib/python3.10/site-packages/airflow/providers/databricks/hooks/databricks_base.py", line 525, in _do_api_call
    response.raise_for_status()
  File "/home/airflow/.local/lib/python3.10/site-packages/requests/models.py", line 1021, in raise_for_status
    raise HTTPError(http_error_msg, response=self)
requests.exceptions.HTTPError: 400 Client Error: Bad Request for url: https://adb-1362567168960874.14.azuredatabricks.net/api/2.1/jobs/runs/submit

During handling of the above exception, another exception occurred:

Traceback (most recent call last):
  File "/home/airflow/.local/lib/python3.10/site-packages/airflow/providers/databricks/operators/databricks.py", line 375, in execute
    self.run_id = self._hook.submit_run(self.json)
  File "/home/airflow/.local/lib/python3.10/site-packages/airflow/providers/databricks/hooks/databricks.py", line 152, in submit_run
    response = self._do_api_call(SUBMIT_RUN_ENDPOINT, json)
  File "/home/airflow/.local/lib/python3.10/site-packages/airflow/providers/databricks/hooks/databricks_base.py", line 531, in _do_api_call
    raise AirflowException(
airflow.exceptions.AirflowException: Response: b'{"error_code":"INVALID_PARAMETER_VALUE","message":"Cluster 1220-163711-icj2y6pc does not exist"}', Status Code: 400
[2023-01-23T11:15:04.483-0300] {taskinstance.py:1322} INFO - Marking task as FAILED. dag_id=raw_opt_t_fatura, task_id=get_last_date, execution_date=20230123T141428, start_date=20230123T141455, end_date=20230123T141504
[2023-01-23T11:15:05.154-0300] {standard_task_runner.py:100} ERROR - Failed to execute job 1172 for task get_last_date (Response: b'{"error_code":"INVALID_PARAMETER_VALUE","message":"Cluster 1220-163711-icj2y6pc does not exist"}', Status Code: 400; 1101145)
[2023-01-23T11:15:05.175-0300] {local_task_job.py:159} INFO - Task exited with return code 1
[2023-01-23T11:15:05.858-0300] {taskinstance.py:2582} INFO - 0 downstream tasks scheduled from follow-on schedule check
